Workbook

Sheet Overview
A1: Appetize AI – Google Ads Keyword Strategy
A2: Prepared | B2: 2026-09-23 · for Google Ads implementation
A3: Product | B3: Appetize AI – 'The mobile layer for your AI agents'. Cloud iOS/Android sandboxes that agents drive via CLI, MCP and CI (Claude Code, Cursor, Codex, Devin, Copilot).
A4: Landing page | B4: https://appetize.io/ai
A6: GOAL
A7: Objective | B7: Awareness + qualified traffic from the people who implement agentic / CLI workflows for mobile: mobile engineers using coding agents, platform/DevEx engineers, QA automation, AI-agent platform builders, and eng managers/heads of mobile.
A8: Core insight | B8: Demand for 'agents + mobile' is new and small (mostly <300/mo per term) but extremely high intent. Winning = own the long tail early (MCP, Claude Code/Cursor + iOS/Android, cloud simulator for CI), while cheaply harvesting broader simulator/testing terms with tight negatives.
A10: TARGET PERSONAS
A11: Mobile Eng (iOS/Android/RN) | B11: Already using Claude Code/Cursor; hitting the 'phone wall' – agent can't see or run the app. Searches: '<agent> ios', 'ios simulator mcp', 'xcode mcp'.
A12: Platform / DevEx Eng | B12: Runs agents in Linux containers & CI; needs simulators via API/CLI. Searches: 'ios simulator linux/docker', 'github actions android emulator', 'cloud ios simulator'.
A13: QA Automation / QA Lead | B13: Evaluating AI testing. Searches: 'ai mobile testing', 'appium mcp', 'agentic qa', incumbent alternatives.
A14: AI / Agent Platform Eng | B14: Building internal agents (Devin-style). Searches: 'ai agent sandbox', 'ai agent mobile app testing'.
A15: Eng Manager / Head of Mobile | B15: Budget owner. Searches: 'ai agents for mobile development', 'test ai generated code', PR preview.
A17: COMPETITOR TAKEAWAYS
A18: Limrun (limrun.com, YC) | B18: 'Remote Xcode, iOS & Android simulators for teams and agents'. Hosted MCP (mcp.limrun.com), `lim` CLI via npm/brew, agent skills, 60fps recording, PR preview links. Closest head-to-head.
A19: Expo EAS Simulator | B19: 'Simulators built for agents' / 'Close the loop on agent-written code'. Early access waitlist, `eas simulator --platform ios`, works with agent-device. React-Native/Expo-centric – Appetize wins on native + any framework, available now.
A20: OSS MCP tools | B20: mobile-mcp, ios-simulator-mcp, XcodeBuildMCP (Sentry), agent-device (Callstack). They drive demand but run locally on a Mac – Appetize angle: 'same workflow, in the cloud, from any Linux agent/CI, in parallel'.
A21: Incumbent device clouds | B21: BrowserStack, Sauce Labs, LambdaTest/TestMu, Firebase Test Lab, AWS Device Farm – heavy, expensive, QA-centric. Appetize angle: instant, browser-streamed, agent-native.
A23: RECOMMENDED STRUCTURE
A24: Campaigns | B24: See 'Campaign Plan' tab. Search campaigns 01–06 plus a Demand Gen campaign using Custom Segments (see 'Audience Segments') because search volume alone is too thin for awareness goals.
A25: Match types | B25: Launch Phrase + Exact on Tier 1; Phrase only on Tier 2; Tier 3 Exact only with low bids. Add Broad only on campaign 02 once conversions >30/mo and Smart Bidding is on.
A26: Bidding | B26: Start Maximize Clicks with CPC cap (use Est. CPC High) for 2–4 weeks to gather data; move to Maximize Conversions / tCPA once demo/signup conversions are tracked.
A27: Geo / language | B27: Start US, CA, UK, DE, NL, Nordics, AU, IL – English. Exclude low-B2B-value geos initially; high share of 'online emulator' traffic is consumer/gaming.
A28: Ad text | B28: Never use competitor trademarks in ad copy (Limrun, Expo, BrowserStack…). Keyword bidding on names is fine. Agent brand names (Claude Code, Cursor) in copy may be restricted – test and review disapprovals.
A30: ⚠ SEARCH VOLUME – READ FIRST
A31: Source of volumes | B31: Volumes are ESTIMATED US monthly searches, built from public Ahrefs/Semrush benchmarks for adjacent head terms (e.g. 'android emulator' ≈49K/mo global per Ahrefs) and scaled for specificity. Live Google Keyword Planner data was NOT available to the author.
A32: Action for specialist | B32: Paste Keyword Planner 'Avg. monthly searches' into the yellow 'Planner Volume' column on the Keywords tab. Priority scores, tiers and campaign rollups recalculate automatically and prefer Planner data when present.
A33: Confidence | B33: High/Medium/Low per row. Many agent/MCP terms are <50/mo or show as '0–10' in Planner – keep them anyway; they are the highest-intent terms and 'low search volume' status often lifts as the category grows.
A35: TABS
A36: Keywords | B36: Master keyword list with volume, intent, persona, relevance, CPC, priority score/tier. Yellow = cells to fill in.
A37: Campaign Plan | B37: Campaign → ad group rollups (keyword count, volume, suggested budget split).
A38: Negatives | B38: Shared negative keyword lists (gaming, consumer, jobs, MCP false positives).
A39: Ad Copy | B39: RSA headline/description starters per campaign with live character counts.
A40: Audience Segments | B40: Custom segment seeds for Demand Gen / YouTube awareness.
A41: Scoring | B41: Weights behind the Priority Score – editable.

Sheet Keywords
A1: # | B1: Campaign | C1: Ad Group | D1: Keyword | E1: Match Type | F1: Est. US Monthly Volume | G1: Planner Volume (fill in) | H1: Volume Used | I1: Volume Confidence | J1: Search Intent | K1: Funnel | L1: Primary Persona | M1: Relevance (1-5) | N1: Competition | O1: Est. CPC Low ($) | P1: Est. CPC High ($) | Q1: Priority Score | R1: Tier | S1: Landing Page | T1: Notes
A2: 1 | B2: 01 Brand – Appetize AI | C2: Brand – AI | D2: appetize ai | E2: Phrase | F2: 20 | H2: =IF(G2<>"",G2,F2) | I2: Low | J2: Navigational | K2: BOFU | L2: All | M2: 5 | N2: Low | O2: 1 | P2: 3 | Q2: =ROUND(Scoring!$B$2*(M2/5)+Scoring!$B$3*MIN(1,LOG10(H2+1)/LOG10(Scoring!$B$4+1))+IF(OR(J2="Commercial",J2="Navigational"),Scoring!$B$5,IF(J2="Solution-aware",Scoring!$B$6,Scoring!$B$7)),0) | R2: =IF(Q2>=Scoring!$B$8,"Tier 1",IF(Q2>=Scoring!$B$9,"Tier 2","Tier 3")) | S2: https://appetize.io/ai | T2: New product; protect before competitors bid
A3: 2 | B3: 01 Brand – Appetize AI | C3: Brand – AI | D3: appetize mcp | E3: Phrase | F3: 10 | H3: =IF(G3<>"",G3,F3) | I3: Low | J3: Navigational | K3: BOFU | L3: Mobile Eng / AI Eng | M3: 5 | N3: Low | O3: 1 | P3: 3 | Q3: =ROUND(Scoring!$B$2*(M3/5)+Scoring!$B$3*MIN(1,LOG10(H3+1)/LOG10(Scoring!$B$4+1))+IF(OR(J3="Commercial",J3="Navigational"),Scoring!$B$5,IF(J3="Solution-aware",Scoring!$B$6,Scoring!$B$7)),0) | R3: =IF(Q3>=Scoring!$B$8,"Tier 1",IF(Q3>=Scoring!$B$9,"Tier 2","Tier 3")) | S3: https://appetize.io/ai
A4: 3 | B4: 01 Brand – Appetize AI | C4: Brand – AI | D4: appetize cli | E4: Phrase | F4: 10 | H4: =IF(G4<>"",G4,F4) | I4: Low | J4: Navigational | K4: BOFU | L4: Platform / DevEx | M4: 5 | N4: Low | O4: 1 | P4: 3 | Q4: =ROUND(Scoring!$B$2*(M4/5)+Scoring!$B$3*MIN(1,LOG10(H4+1)/LOG10(Scoring!$B$4+1))+IF(OR(J4="Commercial",J4="Navigational"),Scoring!$B$5,IF(J4="Solution-aware",Scoring!$B$6,Scoring!$B$7)),0) | R4: =IF(Q4>=Scoring!$B$8,"Tier 1",IF(Q4>=Scoring!$B$9,"Tier 2","Tier 3")) | S4: https://appetize.io/ai
A5: 4 | B5: 01 Brand – Appetize AI | C5: Brand – Core | D5: appetize | E5: Exact | F5: 2400 | H5: =IF(G5<>"",G5,F5) | I5: Medium | J5: Navigational | K5: BOFU | L5: All | M5: 4 | N5: Low | O5: 0.5 | P5: 2 | Q5: =ROUND(Scoring!$B$2*(M5/5)+Scoring!$B$3*MIN(1,LOG10(H5+1)/LOG10(Scoring!$B$4+1))+IF(OR(J5="Commercial",J5="Navigational"),Scoring!$B$5,IF(J5="Solution-aware",Scoring!$B$6,Scoring!$B$7)),0) | R5: =IF(Q5>=Scoring!$B$8,"Tier 1",IF(Q5>=Scoring!$B$9,"Tier 2","Tier 3")) | S5: https://appetize.io/ai | T5: Route existing brand traffic to /ai with sitelink
A6: 5 | B6: 01 Brand – Appetize AI | C6: Brand – Core | D6: appetize.io | E6: Exact | F6: 880 | H6: =IF(G6<>"",G6,F6) | I6: Medium | J6: Navigational | K6: BOFU | L6: All | M6: 4 | N6: Low | O6: 0.5 | P6: 2 | Q6: =ROUND(Scoring!$B$2*(M6/5)+Scoring!$B$3*MIN(1,LOG10(H6+1)/LOG10(Scoring!$B$4+1))+IF(OR(J6="Commercial",J6="Navigational"),Scoring!$B$5,IF(J6="Solution-aware",Scoring!$B$6,Scoring!$B$7)),0) | R6: =IF(Q6>=Scoring!$B$8,"Tier 1",IF(Q6>=Scoring!$B$9,"Tier 2","Tier 3")) | S6: https://appetize.io/ai
A7: 6 | B7: 02 Agents × Mobile (MCP / CLI) | C7: Mobile MCP Server | D7: mobile mcp | E7: Phrase | F7: 260 | H7: =IF(G7<>"",G7,F7) | I7: Low | J7: Commercial | K7: MOFU | L7: Mobile Eng / AI Eng | M7: 5 | N7: Low | O7: 3 | P7: 9 | Q7: =ROUND(Scoring!$B$2*(M7/5)+Scoring!$B$3*MIN(1,LOG10(H7+1)/LOG10(Scoring!$B$4+1))+IF(OR(J7="Commercial",J7="Navigational"),Scoring!$B$5,IF(J7="Solution-aware",Scoring!$B$6,Scoring!$B$7)),0) | R7: =IF(Q7>=Scoring!$B$8,"Tier 1",IF(Q7>=Scoring!$B$9,"Tier 2","Tier 3")) | S7: https://appetize.io/ai | T7: Open-source mobile-next/mobile-mcp drives demand
A8: 7 | B8: 02 Agents × Mobile (MCP / CLI) | C8: Mobile MCP Server | D8: mobile mcp server | E8: Phrase | F8: 110 | H8: =IF(G8<>"",G8,F8) | I8: Low | J8: Commercial | K8: MOFU | L8: Mobile Eng / AI Eng | M8: 5 | N8: Low | O8: 3 | P8: 9 | Q8: =ROUND(Scoring!$B$2*(M8/5)+Scoring!$B$3*MIN(1,LOG10(H8+1)/LOG10(Scoring!$B$4+1))+IF(OR(J8="Commercial",J8="Navigational"),Scoring!$B$5,IF(J8="Solution-aware",Scoring!$B$6,Scoring!$B$7)),0) | R8: =IF(Q8>=Scoring!$B$8,"Tier 1",IF(Q8>=Scoring!$B$9,"Tier 2","Tier 3")) | S8: https://appetize.io/ai
A9: 8 | B9: 02 Agents × Mobile (MCP / CLI) | C9: Mobile MCP Server | D9: mcp server for mobile app testing | E9: Phrase | F9: 50 | H9: =IF(G9<>"",G9,F9) | I9: Low | J9: Commercial | K9: MOFU | L9: QA Automation | M9: 5 | N9: Low | O9: 3 | P9: 9 | Q9: =ROUND(Scoring!$B$2*(M9/5)+Scoring!$B$3*MIN(1,LOG10(H9+1)/LOG10(Scoring!$B$4+1))+IF(OR(J9="Commercial",J9="Navigational"),Scoring!$B$5,IF(J9="Solution-aware",Scoring!$B$6,Scoring!$B$7)),0) | R9: =IF(Q9>=Scoring!$B$8,"Tier 1",IF(Q9>=Scoring!$B$9,"Tier 2","Tier 3")) | S9: https://appetize.io/ai
A10: 9 | B10: 02 Agents × Mobile (MCP / CLI) | C10: Mobile MCP Server | D10: mcp for mobile app development | E10: Phrase | F10: 50 | H10: =IF(G10<>"",G10,F10) | I10: Low | J10: Commercial | K10: MOFU | L10: Mobile Eng | M10: 5 | N10: Low | O10: 3 | P10: 9 | Q10: =ROUND(Scoring!$B$2*(M10/5)+Scoring!$B$3*MIN(1,LOG10(H10+1)/LOG10(Scoring!$B$4+1))+IF(OR(J10="Commercial",J10="Navigational"),Scoring!$B$5,IF(J10="Solution-aware",Scoring!$B$6,Scoring!$B$7)),0) | R10: =IF(Q10>=Scoring!$B$8,"Tier 1",IF(Q10>=Scoring!$B$9,"Tier 2","Tier 3")) | S10: https://appetize.io/ai
A11: 10 | B11: 02 Agents × Mobile (MCP / CLI) | C11: Mobile MCP Server | D11: appium mcp | E11: Phrase | F11: 170 | H11: =IF(G11<>"",G11,F11) | I11: Low | J11: Commercial | K11: MOFU | L11: QA Automation | M11: 4 | N11: Low | O11: 3 | P11: 8 | Q11: =ROUND(Scoring!$B$2*(M11/5)+Scoring!$B$3*MIN(1,LOG10(H11+1)/LOG10(Scoring!$B$4+1))+IF(OR(J11="Commercial",J11="Navigational"),Scoring!$B$5,IF(J11="Solution-aware",Scoring!$B$6,Scoring!$B$7)),0) | R11: =IF(Q11>=Scoring!$B$8,"Tier 1",IF(Q11>=Scoring!$B$9,"Tier 2","Tier 3")) | S11: https://appetize.io/ai
A12: 11 | B12: 02 Agents × Mobile (MCP / CLI) | C12: Mobile MCP Server | D12: maestro mcp | E12: Phrase | F12: 50 | H12: =IF(G12<>"",G12,F12) | I12: Low | J12: Commercial | K12: MOFU | L12: QA Automation | M12: 4 | N12: Low | O12: 3 | P12: 8 | Q12: =ROUND(Scoring!$B$2*(M12/5)+Scoring!$B$3*MIN(1,LOG10(H12+1)/LOG10(Scoring!$B$4+1))+IF(OR(J12="Commercial",J12="Navigational"),Scoring!$B$5,IF(J12="Solution-aware",Scoring!$B$6,Scoring!$B$7)),0) | R12: =IF(Q12>=Scoring!$B$8,"Tier 1",IF(Q12>=Scoring!$B$9,"Tier 2","Tier 3")) | S12: https://appetize.io/ai
A13: 12 | B13: 02 Agents × Mobile (MCP / CLI) | C13: iOS Simulator MCP | D13: ios simulator mcp | E13: Phrase | F13: 170 | H13: =IF(G13<>"",G13,F13) | I13: Low | J13: Commercial | K13: MOFU | L13: iOS Eng | M13: 5 | N13: Low | O13: 3 | P13: 10 | Q13: =ROUND(Scoring!$B$2*(M13/5)+Scoring!$B$3*MIN(1,LOG10(H13+1)/LOG10(Scoring!$B$4+1))+IF(OR(J13="Commercial",J13="Navigational"),Scoring!$B$5,IF(J13="Solution-aware",Scoring!$B$6,Scoring!$B$7)),0) | R13: =IF(Q13>=Scoring!$B$8,"Tier 1",IF(Q13>=Scoring!$B$9,"Tier 2","Tier 3")) | S13: https://appetize.io/ai | T13: joshuayoes/ios-simulator-mcp is referenced in Anthropic's Claude Code best practices
A14: 13 | B14: 02 Agents × Mobile (MCP / CLI) | C14: iOS Simulator MCP | D14: xcode mcp | E14: Phrase | F14: 480 | H14: =IF(G14<>"",G14,F14) | I14: Low | J14: Commercial | K14: MOFU | L14: iOS Eng | M14: 4 | N14: Medium | O14: 3 | P14: 10 | Q14: =ROUND(Scoring!$B$2*(M14/5)+Scoring!$B$3*MIN(1,LOG10(H14+1)/LOG10(Scoring!$B$4+1))+IF(OR(J14="Commercial",J14="Navigational"),Scoring!$B$5,IF(J14="Solution-aware",Scoring!$B$6,Scoring!$B$7)),0) | R14: =IF(Q14>=Scoring!$B$8,"Tier 1",IF(Q14>=Scoring!$B$9,"Tier 2","Tier 3")) | S14: https://appetize.io/ai | T14: Includes Apple Xcode MCP searches; watch search terms
A15: 14 | B15: 02 Agents × Mobile (MCP / CLI) | C15: iOS Simulator MCP | D15: xcodebuildmcp | E15: Phrase | F15: 390 | H15: =IF(G15<>"",G15,F15) | I15: Low | J15: Commercial | K15: MOFU | L15: iOS Eng | M15: 4 | N15: Low | O15: 2 | P15: 8 | Q15: =ROUND(Scoring!$B$2*(M15/5)+Scoring!$B$3*MIN(1,LOG10(H15+1)/LOG10(Scoring!$B$4+1))+IF(OR(J15="Commercial",J15="Navigational"),Scoring!$B$5,IF(J15="Solution-aware",Scoring!$B$6,Scoring!$B$7)),0) | R15: =IF(Q15>=Scoring!$B$8,"Tier 1",IF(Q15>=Scoring!$B$9,"Tier 2","Tier 3")) | S15: https://appetize.io/ai | T15: Sentry OSS; complement not replace – message 'run it in the cloud'
A16: 15 | B16: 02 Agents × Mobile (MCP / CLI) | C16: iOS Simulator MCP | D16: ios mcp server | E16: Phrase | F16: 70 | H16: =IF(G16<>"",G16,F16) | I16: Low | J16: Commercial | K16: MOFU | L16: iOS Eng | M16: 5 | N16: Low | O16: 3 | P16: 9 | Q16: =ROUND(Scoring!$B$2*(M16/5)+Scoring!$B$3*MIN(1,LOG10(H16+1)/LOG10(Scoring!$B$4+1))+IF(OR(J16="Commercial",J16="Navigational"),Scoring!$B$5,IF(J16="Solution-aware",Scoring!$B$6,Scoring!$B$7)),0) | R16: =IF(Q16>=Scoring!$B$8,"Tier 1",IF(Q16>=Scoring!$B$9,"Tier 2","Tier 3")) | S16: https://appetize.io/ai
A17: 16 | B17: 02 Agents × Mobile (MCP / CLI) | C17: Android Emulator MCP | D17: android mcp | E17: Phrase | F17: 140 | H17: =IF(G17<>"",G17,F17) | I17: Low | J17: Commercial | K17: MOFU | L17: Android Eng | M17: 5 | N17: Low | O17: 3 | P17: 9 | Q17: =ROUND(Scoring!$B$2*(M17/5)+Scoring!$B$3*MIN(1,LOG10(H17+1)/LOG10(Scoring!$B$4+1))+IF(OR(J17="Commercial",J17="Navigational"),Scoring!$B$5,IF(J17="Solution-aware",Scoring!$B$6,Scoring!$B$7)),0) | R17: =IF(Q17>=Scoring!$B$8,"Tier 1",IF(Q17>=Scoring!$B$9,"Tier 2","Tier 3")) | S17: https://appetize.io/ai
A18: 17 | B18: 02 Agents × Mobile (MCP / CLI) | C18: Android Emulator MCP | D18: android emulator mcp | E18: Phrase | F18: 50 | H18: =IF(G18<>"",G18,F18) | I18: Low | J18: Commercial | K18: MOFU | L18: Android Eng | M18: 5 | N18: Low | O18: 3 | P18: 9 | Q18: =ROUND(Scoring!$B$2*(M18/5)+Scoring!$B$3*MIN(1,LOG10(H18+1)/LOG10(Scoring!$B$4+1))+IF(OR(J18="Commercial",J18="Navigational"),Scoring!$B$5,IF(J18="Solution-aware",Scoring!$B$6,Scoring!$B$7)),0) | R18: =IF(Q18>=Scoring!$B$8,"Tier 1",IF(Q18>=Scoring!$B$9,"Tier 2","Tier 3")) | S18: https://appetize.io/ai
A19: 18 | B19: 02 Agents × Mobile (MCP / CLI) | C19: Android Emulator MCP | D19: adb mcp server | E19: Phrase | F19: 40 | H19: =IF(G19<>"",G19,F19) | I19: Low | J19: Commercial | K19: MOFU | L19: Android Eng | M19: 4 | N19: Low | O19: 2 | P19: 8 | Q19: =ROUND(Scoring!$B$2*(M19/5)+Scoring!$B$3*MIN(1,LOG10(H19+1)/LOG10(Scoring!$B$4+1))+IF(OR(J19="Commercial",J19="Navigational"),Scoring!$B$5,IF(J19="Solution-aware",Scoring!$B$6,Scoring!$B$7)),0) | R19: =IF(Q19>=Scoring!$B$8,"Tier 1",IF(Q19>=Scoring!$B$9,"Tier 2","Tier 3")) | S19: https://appetize.io/ai
A20: 19 | B20: 02 Agents × Mobile (MCP / CLI) | C20: Coding Agent + Mobile | D20: claude code ios development | E20: Phrase | F20: 170 | H20: =IF(G20<>"",G20,F20) | I20: Low | J20: Solution-aware | K20: MOFU | L20: iOS Eng | M20: 5 | N20: Low | O20: 2 | P20: 8 | Q20: =ROUND(Scoring!$B$2*(M20/5)+Scoring!$B$3*MIN(1,LOG10(H20+1)/LOG10(Scoring!$B$4+1))+IF(OR(J20="Commercial",J20="Navigational"),Scoring!$B$5,IF(J20="Solution-aware",Scoring!$B$6,Scoring!$B$7)),0) | R20: =IF(Q20>=Scoring!$B$8,"Tier 1",IF(Q20>=Scoring!$B$9,"Tier 2","Tier 3")) | S20: https://appetize.io/ai
A21: 20 | B21: 02 Agents × Mobile (MCP / CLI) | C21: Coding Agent + Mobile | D21: claude code mobile app | E21: Phrase | F21: 260 | H21: =IF(G21<>"",G21,F21) | I21: Low | J21: Solution-aware | K21: MOFU | L21: Mobile Eng | M21: 5 | N21: Low | O21: 2 | P21: 8 | Q21: =ROUND(Scoring!$B$2*(M21/5)+Scoring!$B$3*MIN(1,LOG10(H21+1)/LOG10(Scoring!$B$4+1))+IF(OR(J21="Commercial",J21="Navigational"),Scoring!$B$5,IF(J21="Solution-aware",Scoring!$B$6,Scoring!$B$7)),0) | R21: =IF(Q21>=Scoring!$B$8,"Tier 1",IF(Q21>=Scoring!$B$9,"Tier 2","Tier 3")) | S21: https://appetize.io/ai
A22: 21 | B22: 02 Agents × Mobile (MCP / CLI) | C22: Coding Agent + Mobile | D22: claude code android | E22: Phrase | F22: 110 | H22: =IF(G22<>"",G22,F22) | I22: Low | J22: Solution-aware | K22: MOFU | L22: Android Eng | M22: 5 | N22: Low | O22: 2 | P22: 8 | Q22: =ROUND(Scoring!$B$2*(M22/5)+Scoring!$B$3*MIN(1,LOG10(H22+1)/LOG10(Scoring!$B$4+1))+IF(OR(J22="Commercial",J22="Navigational"),Scoring!$B$5,IF(J22="Solution-aware",Scoring!$B$6,Scoring!$B$7)),0) | R22: =IF(Q22>=Scoring!$B$8,"Tier 1",IF(Q22>=Scoring!$B$9,"Tier 2","Tier 3")) | S22: https://appetize.io/ai
A23: 22 | B23: 02 Agents × Mobile (MCP / CLI) | C23: Coding Agent + Mobile | D23: claude code xcode | E23: Phrase | F23: 320 | H23: =IF(G23<>"",G23,F23) | I23: Low | J23: Solution-aware | K23: MOFU | L23: iOS Eng | M23: 4 | N23: Low | O23: 2 | P23: 8 | Q23: =ROUND(Scoring!$B$2*(M23/5)+Scoring!$B$3*MIN(1,LOG10(H23+1)/LOG10(Scoring!$B$4+1))+IF(OR(J23="Commercial",J23="Navigational"),Scoring!$B$5,IF(J23="Solution-aware",Scoring!$B$6,Scoring!$B$7)),0) | R23: =IF(Q23>=Scoring!$B$8,"Tier 1",IF(Q23>=Scoring!$B$9,"Tier 2","Tier 3")) | S23: https://appetize.io/ai
A24: 23 | B24: 02 Agents × Mobile (MCP / CLI) | C24: Coding Agent + Mobile | D24: claude code ios simulator | E24: Phrase | F24: 70 | H24: =IF(G24<>"",G24,F24) | I24: Low | J24: Solution-aware | K24: MOFU | L24: iOS Eng | M24: 5 | N24: Low | O24: 2 | P24: 8 | Q24: =ROUND(Scoring!$B$2*(M24/5)+Scoring!$B$3*MIN(1,LOG10(H24+1)/LOG10(Scoring!$B$4+1))+IF(OR(J24="Commercial",J24="Navigational"),Scoring!$B$5,IF(J24="Solution-aware",Scoring!$B$6,Scoring!$B$7)),0) | R24: =IF(Q24>=Scoring!$B$8,"Tier 1",IF(Q24>=Scoring!$B$9,"Tier 2","Tier 3")) | S24: https://appetize.io/ai
A25: 24 | B25: 02 Agents × Mobile (MCP / CLI) | C25: Coding Agent + Mobile | D25: cursor ios development | E25: Phrase | F25: 210 | H25: =IF(G25<>"",G25,F25) | I25: Low | J25: Solution-aware | K25: MOFU | L25: iOS Eng | M25: 4 | N25: Low | O25: 2 | P25: 8 | Q25: =ROUND(Scoring!$B$2*(M25/5)+Scoring!$B$3*MIN(1,LOG10(H25+1)/LOG10(Scoring!$B$4+1))+IF(OR(J25="Commercial",J25="Navigational"),Scoring!$B$5,IF(J25="Solution-aware",Scoring!$B$6,Scoring!$B$7)),0) | R25: =IF(Q25>=Scoring!$B$8,"Tier 1",IF(Q25>=Scoring!$B$9,"Tier 2","Tier 3")) | S25: https://appetize.io/ai
A26: 25 | B26: 02 Agents × Mobile (MCP / CLI) | C26: Coding Agent + Mobile | D26: cursor mobile app development | E26: Phrase | F26: 140 | H26: =IF(G26<>"",G26,F26) | I26: Low | J26: Solution-aware | K26: MOFU | L26: Mobile Eng | M26: 4 | N26: Low | O26: 2 | P26: 8 | Q26: =ROUND(Scoring!$B$2*(M26/5)+Scoring!$B$3*MIN(1,LOG10(H26+1)/LOG10(Scoring!$B$4+1))+IF(OR(J26="Commercial",J26="Navigational"),Scoring!$B$5,IF(J26="Solution-aware",Scoring!$B$6,Scoring!$B$7)),0) | R26: =IF(Q26>=Scoring!$B$8,"Tier 1",IF(Q26>=Scoring!$B$9,"Tier 2","Tier 3")) | S26: https://appetize.io/ai
A27: 26 | B27: 02 Agents × Mobile (MCP / CLI) | C27: Coding Agent + Mobile | D27: codex ios development | E27: Phrase | F27: 90 | H27: =IF(G27<>"",G27,F27) | I27: Low | J27: Solution-aware | K27: MOFU | L27: iOS Eng | M27: 4 | N27: Low | O27: 2 | P27: 8 | Q27: =ROUND(Scoring!$B$2*(M27/5)+Scoring!$B$3*MIN(1,LOG10(H27+1)/LOG10(Scoring!$B$4+1))+IF(OR(J27="Commercial",J27="Navigational"),Scoring!$B$5,IF(J27="Solution-aware",Scoring!$B$6,Scoring!$B$7)),0) | R27: =IF(Q27>=Scoring!$B$8,"Tier 1",IF(Q27>=Scoring!$B$9,"Tier 2","Tier 3")) | S27: https://appetize.io/ai
... A31: 30 | B31: 02 Agents × Mobile (MCP / CLI) | C31: Coding Agent + Mobile | D31: copilot coding agent ios | E31: Phrase | F31: 30 | H31: =IF(G31<>"",G31,F31) | I31: Low | J31: Solution-aware | K31: MOFU | L31: iOS Eng | M31: 4 | N31: Low | O31: 2 | P31: 7 | Q31: =ROUND(Scoring!$B$2*(M31/5)+Scoring!$B$3*MIN(1,LOG10(H31+1)/LOG10(Scoring!$B$4+1))+IF(OR(J31="Commercial",J31="Navigational"),Scoring!$B$5,IF(J31="Solution-aware",Scoring!$B$6,Scoring!$B$7)),0) | R31: =IF(Q31>=Scoring!$B$8,"Tier 1",IF(Q31>=Scoring!$B$9,"Tier 2","Tier 3")) | S31: https://appetize.io/ai
A32: 31 | B32: 02 Agents × Mobile (MCP / CLI) | C32: Agent Sandbox / Infra | D32: ai agent sandbox | E32: Phrase | F32: 480 | H32: =IF(G32<>"",G32,F32) | I32: Medium | J32: Commercial | K32: MOFU | L32: AI / Agent Platform Eng | M32: 4 | N32: Medium | O32: 4 | P32: 12 | Q32: =ROUND(Scoring!$B$2*(M32/5)+Scoring!$B$3*MIN(1,LOG10(H32+1)/LOG10(Scoring!$B$4+1))+IF(OR(J32="Commercial",J32="Navigational"),Scoring!$B$5,IF(J32="Solution-aware",Scoring!$B$6,Scoring!$B$7)),0) | R32: =IF(Q32>=Scoring!$B$8,"Tier 1",IF(Q32>=Scoring!$B$9,"Tier 2","Tier 3")) | S32: https://appetize.io/ai | T32: Dominated by code sandboxes (E2B, Daytona); qualify with 'mobile' in ads
A33: 32 | B33: 02 Agents × Mobile (MCP / CLI) | C33: Agent Sandbox / Infra | D33: sandbox for ai agents | E33: Phrase | F33: 260 | H33: =IF(G33<>"",G33,F33) | I33: Low | J33: Commercial | K33: MOFU | L33: AI / Agent Platform Eng | M33: 4 | N33: Medium | O33: 4 | P33: 12 | Q33: =ROUND(Scoring!$B$2*(M33/5)+Scoring!$B$3*MIN(1,LOG10(H33+1)/LOG10(Scoring!$B$4+1))+IF(OR(J33="Commercial",J33="Navigational"),Scoring!$B$5,IF(J33="Solution-aware",Scoring!$B$6,Scoring!$B$7)),0) | R33: =IF(Q33>=Scoring!$B$8,"Tier 1",IF(Q33>=Scoring!$B$9,"Tier 2","Tier 3")) | S33: https://appetize.io/ai
A34: 33 | B34: 02 Agents × Mobile (MCP / CLI) | C34: Agent Sandbox / Infra | D34: mobile sandbox for ai agents | E34: Phrase | F34: 20 | H34: =IF(G34<>"",G34,F34) | I34: Low | J34: Commercial | K34: BOFU | L34: AI / Agent Platform Eng | M34: 5 | N34: Low | O34: 3 | P34: 10 | Q34: =ROUND(Scoring!$B$2*(M34/5)+Scoring!$B$3*MIN(1,LOG10(H34+1)/LOG10(Scoring!$B$4+1))+IF(OR(J34="Commercial",J34="Navigational"),Scoring!$B$5,IF(J34="Solution-aware",Scoring!$B$6,Scoring!$B$7)),0) | R34: =IF(Q34>=Scoring!$B$8,"Tier 1",IF(Q34>=Scoring!$B$9,"Tier 2","Tier 3")) | S34: https://appetize.io/ai | T34: Mirrors Appetize headline
A35: 34 | B35: 02 Agents × Mobile (MCP / CLI) | C35: Agent Sandbox / Infra | D35: ai agent mobile app testing | E35: Phrase | F35: 70 | H35: =IF(G35<>"",G35,F35) | I35: Low | J35: Commercial | K35: MOFU | L35: AI / Agent Platform Eng | M35: 5 | N35: Low | O35: 3 | P35: 10 | Q35: =ROUND(Scoring!$B$2*(M35/5)+Scoring!$B$3*MIN(1,LOG10(H35+1)/LOG10(Scoring!$B$4+1))+IF(OR(J35="Commercial",J35="Navigational"),Scoring!$B$5,IF(J35="Solution-aware",Scoring!$B$6,Scoring!$B$7)),0) | R35: =IF(Q35>=Scoring!$B$8,"Tier 1",IF(Q35>=Scoring!$B$9,"Tier 2","Tier 3")) | S35: https://appetize.io/ai
A36: 35 | B36: 02 Agents × Mobile (MCP / CLI) | C36: Agent Sandbox / Infra | D36: ai agent control android | E36: Phrase | F36: 50 | H36: =IF(G36<>"",G36,F36) | I36: Low | J36: Solution-aware | K36: TOFU | L36: AI / Agent Platform Eng | M36: 4 | N36: Low | O36: 2 | P36: 7 | Q36: =ROUND(Scoring!$B$2*(M36/5)+Scoring!$B$3*MIN(1,LOG10(H36+1)/LOG10(Scoring!$B$4+1))+IF(OR(J36="Commercial",J36="Navigational"),Scoring!$B$5,IF(J36="Solution-aware",Scoring!$B$6,Scoring!$B$7)),0) | R36: =IF(Q36>=Scoring!$B$8,"Tier 1",IF(Q36>=Scoring!$B$9,"Tier 2","Tier 3")) | S36: https://appetize.io/ai
A37: 36 | B37: 02 Agents × Mobile (MCP / CLI) | C37: Agent Sandbox / Infra | D37: computer use agent mobile | E37: Phrase | F37: 30 | H37: =IF(G37<>"",G37,F37) | I37: Low | J37: Solution-aware | K37: TOFU | L37: AI / Agent Platform Eng | M37: 4 | N37: Low | O37: 2 | P37: 7 | Q37: =ROUND(Scoring!$B$2*(M37/5)+Scoring!$B$3*MIN(1,LOG10(H37+1)/LOG10(Scoring!$B$4+1))+IF(OR(J37="Commercial",J37="Navigational"),Scoring!$B$5,IF(J37="Solution-aware",Scoring!$B$6,Scoring!$B$7)),0) | R37: =IF(Q37>=Scoring!$B$8,"Tier 1",IF(Q37>=Scoring!$B$9,"Tier 2","Tier 3")) | S37: https://appetize.io/ai
A38: 37 | B38: 02 Agents × Mobile (MCP / CLI) | C38: Agent Sandbox / Infra | D38: simulators for ai agents | E38: Phrase | F38: 20 | H38: =IF(G38<>"",G38,F38) | I38: Low | J38: Commercial | K38: BOFU | L38: AI / Agent Platform Eng | M38: 5 | N38: Low | O38: 3 | P38: 10 | Q38: =ROUND(Scoring!$B$2*(M38/5)+Scoring!$B$3*MIN(1,LOG10(H38+1)/LOG10(Scoring!$B$4+1))+IF(OR(J38="Commercial",J38="Navigational"),Scoring!$B$5,IF(J38="Solution-aware",Scoring!$B$6,Scoring!$B$7)),0) | R38: =IF(Q38>=Scoring!$B$8,"Tier 1",IF(Q38>=Scoring!$B$9,"Tier 2","Tier 3")) | S38: https://appetize.io/ai | T38: Expo's headline term
A39: 38 | B39: 03 Cloud Simulators for Dev & CI | C39: Cloud iOS Simulator | D39: ios simulator online | E39: Phrase | F39: 1600 | H39: =IF(G39<>"",G39,F39) | I39: Medium | J39: Commercial | K39: MOFU | L39: Mobile Eng / QA | M39: 4 | N39: Medium | O39: 2 | P39: 7 | Q39: =ROUND(Scoring!$B$2*(M39/5)+Scoring!$B$3*MIN(1,LOG10(H39+1)/LOG10(Scoring!$B$4+1))+IF(OR(J39="Commercial",J39="Navigational"),Scoring!$B$5,IF(J39="Solution-aware",Scoring!$B$6,Scoring!$B$7)),0) | R39: =IF(Q39>=Scoring!$B$8,"Tier 1",IF(Q39>=Scoring!$B$9,"Tier 2","Tier 3")) | S39: https://appetize.io/ai | T39: Mixed with consumers; heavy negatives required
A40: 39 | B40: 03 Cloud Simulators for Dev & CI | C40: Cloud iOS Simulator | D40: cloud ios simulator | E40: Phrase | F40: 90 | H40: =IF(G40<>"",G40,F40) | I40: Low | J40: Commercial | K40: BOFU | L40: Platform / DevEx | M40: 5 | N40: Low | O40: 3 | P40: 9 | Q40: =ROUND(Scoring!$B$2*(M40/5)+Scoring!$B$3*MIN(1,LOG10(H40+1)/LOG10(Scoring!$B$4+1))+IF(OR(J40="Commercial",J40="Navigational"),Scoring!$B$5,IF(J40="Solution-aware",Scoring!$B$6,Scoring!$B$7)),0) | R40: =IF(Q40>=Scoring!$B$8,"Tier 1",IF(Q40>=Scoring!$B$9,"Tier 2","Tier 3")) | S40: https://appetize.io/ai
A41: 40 | B41: 03 Cloud Simulators for Dev & CI | C41: Cloud iOS Simulator | D41: remote ios simulator | E41: Phrase | F41: 70 | H41: =IF(G41<>"",G41,F41) | I41: Low | J41: Commercial | K41: BOFU | L41: Platform / DevEx | M41: 5 | N41: Low | O41: 3 | P41: 9 | Q41: =ROUND(Scoring!$B$2*(M41/5)+Scoring!$B$3*MIN(1,LOG10(H41+1)/LOG10(Scoring!$B$4+1))+IF(OR(J41="Commercial",J41="Navigational"),Scoring!$B$5,IF(J41="Solution-aware",Scoring!$B$6,Scoring!$B$7)),0) | R41: =IF(Q41>=Scoring!$B$8,"Tier 1",IF(Q41>=Scoring!$B$9,"Tier 2","Tier 3")) | S41: https://appetize.io/ai
A42: 41 | B42: 03 Cloud Simulators for Dev & CI | C42: Cloud iOS Simulator | D42: ios simulator in browser | E42: Phrase | F42: 140 | H42: =IF(G42<>"",G42,F42) | I42: Low | J42: Commercial | K42: MOFU | L42: Mobile Eng / QA | M42: 4 | N42: Low | O42: 2 | P42: 6 | Q42: =ROUND(Scoring!$B$2*(M42/5)+Scoring!$B$3*MIN(1,LOG10(H42+1)/LOG10(Scoring!$B$4+1))+IF(OR(J42="Commercial",J42="Navigational"),Scoring!$B$5,IF(J42="Solution-aware",Scoring!$B$6,Scoring!$B$7)),0) | R42: =IF(Q42>=Scoring!$B$8,"Tier 1",IF(Q42>=Scoring!$B$9,"Tier 2","Tier 3")) | S42: https://appetize.io/ai
A43: 42 | B43: 03 Cloud Simulators for Dev & CI | C43: Cloud iOS Simulator | D43: ios simulator api | E43: Phrase | F43: 50 | H43: =IF(G43<>"",G43,F43) | I43: Low | J43: Commercial | K43: BOFU | L43: Platform / DevEx | M43: 5 | N43: Low | O43: 3 | P43: 9 | Q43: =ROUND(Scoring!$B$2*(M43/5)+Scoring!$B$3*MIN(1,LOG10(H43+1)/LOG10(Scoring!$B$4+1))+IF(OR(J43="Commercial",J43="Navigational"),Scoring!$B$5,IF(J43="Solution-aware",Scoring!$B$6,Scoring!$B$7)),0) | R43: =IF(Q43>=Scoring!$B$8,"Tier 1",IF(Q43>=Scoring!$B$9,"Tier 2","Tier 3")) | S43: https://appetize.io/ai
...

Sheet Campaign Plan
A1: Campaign | B1: Ad Group | C1: # Keywords | D1: Total Volume Used | E1: Avg Priority Score | F1: # Tier 1 | G1: Avg Est. CPC High ($) | H1: Budget Share (campaign) | I1: Role
A2: 01 Brand – Appetize AI | B2: Brand – AI | C2: =COUNTIFS(Keywords!$B$2:$B$97,A2,Keywords!$C$2:$C$97,B2) | D2: =SUMIFS(Keywords!$H$2:$H$97,Keywords!$B$2:$B$97,A2,Keywords!$C$2:$C$97,B2) | E2: =ROUND(AVERAGEIFS(Keywords!$Q$2:$Q$97,Keywords!$B$2:$B$97,A2,Keywords!$C$2:$C$97,B2),0) | F2: =COUNTIFS(Keywords!$B$2:$B$97,A2,Keywords!$C$2:$C$97,B2,Keywords!$R$2:$R$97,"Tier 1") | G2: =AVERAGEIFS(Keywords!$P$2:$P$97,Keywords!$B$2:$B$97,A2,Keywords!$C$2:$C$97,B2) | H2: 0.05 | I2: Protect brand + new 'Appetize AI' terms; sitelinks to /ai, CLI docs, MCP.
A3: 01 Brand – Appetize AI | B3: Brand – Core | C3: =COUNTIFS(Keywords!$B$2:$B$97,A3,Keywords!$C$2:$C$97,B3) | D3: =SUMIFS(Keywords!$H$2:$H$97,Keywords!$B$2:$B$97,A3,Keywords!$C$2:$C$97,B3) | E3: =ROUND(AVERAGEIFS(Keywords!$Q$2:$Q$97,Keywords!$B$2:$B$97,A3,Keywords!$C$2:$C$97,B3),0) | F3: =COUNTIFS(Keywords!$B$2:$B$97,A3,Keywords!$C$2:$C$97,B3,Keywords!$R$2:$R$97,"Tier 1") | G3: =AVERAGEIFS(Keywords!$P$2:$P$97,Keywords!$B$2:$B$97,A3,Keywords!$C$2:$C$97,B3)
A4: 02 Agents × Mobile (MCP / CLI) | B4: Mobile MCP Server | C4: =COUNTIFS(Keywords!$B$2:$B$97,A4,Keywords!$C$2:$C$97,B4) | D4: =SUMIFS(Keywords!$H$2:$H$97,Keywords!$B$2:$B$97,A4,Keywords!$C$2:$C$97,B4) | E4: =ROUND(AVERAGEIFS(Keywords!$Q$2:$Q$97,Keywords!$B$2:$B$97,A4,Keywords!$C$2:$C$97,B4),0) | F4: =COUNTIFS(Keywords!$B$2:$B$97,A4,Keywords!$C$2:$C$97,B4,Keywords!$R$2:$R$97,"Tier 1") | G4: =AVERAGEIFS(Keywords!$P$2:$P$97,Keywords!$B$2:$B$97,A4,Keywords!$C$2:$C$97,B4) | H4: 0.35 | I4: Core. Highest-intent 'agents + mobile' long tail. Launch first, bid aggressively for top of page.
A5: 02 Agents × Mobile (MCP / CLI) | B5: iOS Simulator MCP | C5: =COUNTIFS(Keywords!$B$2:$B$97,A5,Keywords!$C$2:$C$97,B5) | D5: =SUMIFS(Keywords!$H$2:$H$97,Keywords!$B$2:$B$97,A5,Keywords!$C$2:$C$97,B5) | E5: =ROUND(AVERAGEIFS(Keywords!$Q$2:$Q$97,Keywords!$B$2:$B$97,A5,Keywords!$C$2:$C$97,B5),0) | F5: =COUNTIFS(Keywords!$B$2:$B$97,A5,Keywords!$C$2:$C$97,B5,Keywords!$R$2:$R$97,"Tier 1") | G5: =AVERAGEIFS(Keywords!$P$2:$P$97,Keywords!$B$2:$B$97,A5,Keywords!$C$2:$C$97,B5)
A6: 02 Agents × Mobile (MCP / CLI) | B6: Android Emulator MCP | C6: =COUNTIFS(Keywords!$B$2:$B$97,A6,Keywords!$C$2:$C$97,B6) | D6: =SUMIFS(Keywords!$H$2:$H$97,Keywords!$B$2:$B$97,A6,Keywords!$C$2:$C$97,B6) | E6: =ROUND(AVERAGEIFS(Keywords!$Q$2:$Q$97,Keywords!$B$2:$B$97,A6,Keywords!$C$2:$C$97,B6),0) | F6: =COUNTIFS(Keywords!$B$2:$B$97,A6,Keywords!$C$2:$C$97,B6,Keywords!$R$2:$R$97,"Tier 1") | G6: =AVERAGEIFS(Keywords!$P$2:$P$97,Keywords!$B$2:$B$97,A6,Keywords!$C$2:$C$97,B6)
A7: 02 Agents × Mobile (MCP / CLI) | B7: Coding Agent + Mobile | C7: =COUNTIFS(Keywords!$B$2:$B$97,A7,Keywords!$C$2:$C$97,B7) | D7: =SUMIFS(Keywords!$H$2:$H$97,Keywords!$B$2:$B$97,A7,Keywords!$C$2:$C$97,B7) | E7: =ROUND(AVERAGEIFS(Keywords!$Q$2:$Q$97,Keywords!$B$2:$B$97,A7,Keywords!$C$2:$C$97,B7),0) | F7: =COUNTIFS(Keywords!$B$2:$B$97,A7,Keywords!$C$2:$C$97,B7,Keywords!$R$2:$R$97,"Tier 1") | G7: =AVERAGEIFS(Keywords!$P$2:$P$97,Keywords!$B$2:$B$97,A7,Keywords!$C$2:$C$97,B7)
A8: 02 Agents × Mobile (MCP / CLI) | B8: Agent Sandbox / Infra | C8: =COUNTIFS(Keywords!$B$2:$B$97,A8,Keywords!$C$2:$C$97,B8) | D8: =SUMIFS(Keywords!$H$2:$H$97,Keywords!$B$2:$B$97,A8,Keywords!$C$2:$C$97,B8) | E8: =ROUND(AVERAGEIFS(Keywords!$Q$2:$Q$97,Keywords!$B$2:$B$97,A8,Keywords!$C$2:$C$97,B8),0) | F8: =COUNTIFS(Keywords!$B$2:$B$97,A8,Keywords!$C$2:$C$97,B8,Keywords!$R$2:$R$97,"Tier 1") | G8: =AVERAGEIFS(Keywords!$P$2:$P$97,Keywords!$B$2:$B$97,A8,Keywords!$C$2:$C$97,B8)
A9: 03 Cloud Simulators for Dev & CI | B9: Cloud iOS Simulator | C9: =COUNTIFS(Keywords!$B$2:$B$97,A9,Keywords!$C$2:$C$97,B9) | D9: =SUMIFS(Keywords!$H$2:$H$97,Keywords!$B$2:$B$97,A9,Keywords!$C$2:$C$97,B9) | E9: =ROUND(AVERAGEIFS(Keywords!$Q$2:$Q$97,Keywords!$B$2:$B$97,A9,Keywords!$C$2:$C$97,B9),0) | F9: =COUNTIFS(Keywords!$B$2:$B$97,A9,Keywords!$C$2:$C$97,B9,Keywords!$R$2:$R$97,"Tier 1") | G9: =AVERAGEIFS(Keywords!$P$2:$P$97,Keywords!$B$2:$B$97,A9,Keywords!$C$2:$C$97,B9) | H9: 0.22 | I9: Harvest cloud simulator / CI / Linux demand from platform & DevEx engineers.
A10: 03 Cloud Simulators for Dev & CI | B10: Cloud Android Emulator | C10: =COUNTIFS(Keywords!$B$2:$B$97,A10,Keywords!$C$2:$C$97,B10) | D10: =SUMIFS(Keywords!$H$2:$H$97,Keywords!$B$2:$B$97,A10,Keywords!$C$2:$C$97,B10) | E10: =ROUND(AVERAGEIFS(Keywords!$Q$2:$Q$97,Keywords!$B$2:$B$97,A10,Keywords!$C$2:$C$97,B10),0) | F10: =COUNTIFS(Keywords!$B$2:$B$97,A10,Keywords!$C$2:$C$97,B10,Keywords!$R$2:$R$97,"Tier 1") | G10: =AVERAGEIFS(Keywords!$P$2:$P$97,Keywords!$B$2:$B$97,A10,Keywords!$C$2:$C$97,B10)
A11: 03 Cloud Simulators for Dev & CI | B11: Simulators in CI/CD | C11: =COUNTIFS(Keywords!$B$2:$B$97,A11,Keywords!$C$2:$C$97,B11) | D11: =SUMIFS(Keywords!$H$2:$H$97,Keywords!$B$2:$B$97,A11,Keywords!$C$2:$C$97,B11) | E11: =ROUND(AVERAGEIFS(Keywords!$Q$2:$Q$97,Keywords!$B$2:$B$97,A11,Keywords!$C$2:$C$97,B11),0) | F11: =COUNTIFS(Keywords!$B$2:$B$97,A11,Keywords!$C$2:$C$97,B11,Keywords!$R$2:$R$97,"Tier 1") | G11: =AVERAGEIFS(Keywords!$P$2:$P$97,Keywords!$B$2:$B$97,A11,Keywords!$C$2:$C$97,B11)
A12: 03 Cloud Simulators for Dev & CI | B12: Headless / Docker | C12: =COUNTIFS(Keywords!$B$2:$B$97,A12,Keywords!$C$2:$C$97,B12) | D12: =SUMIFS(Keywords!$H$2:$H$97,Keywords!$B$2:$B$97,A12,Keywords!$C$2:$C$97,B12) | E12: =ROUND(AVERAGEIFS(Keywords!$Q$2:$Q$97,Keywords!$B$2:$B$97,A12,Keywords!$C$2:$C$97,B12),0) | F12: =COUNTIFS(Keywords!$B$2:$B$97,A12,Keywords!$C$2:$C$97,B12,Keywords!$R$2:$R$97,"Tier 1") | G12: =AVERAGEIFS(Keywords!$P$2:$P$97,Keywords!$B$2:$B$97,A12,Keywords!$C$2:$C$97,B12)
A13: 03 Cloud Simulators for Dev & CI | B13: iOS Dev Without a Mac | C13: =COUNTIFS(Keywords!$B$2:$B$97,A13,Keywords!$C$2:$C$97,B13) | D13: =SUMIFS(Keywords!$H$2:$H$97,Keywords!$B$2:$B$97,A13,Keywords!$C$2:$C$97,B13) | E13: =ROUND(AVERAGEIFS(Keywords!$Q$2:$Q$97,Keywords!$B$2:$B$97,A13,Keywords!$C$2:$C$97,B13),0) | F13: =COUNTIFS(Keywords!$B$2:$B$97,A13,Keywords!$C$2:$C$97,B13,Keywords!$R$2:$R$97,"Tier 1") | G13: =AVERAGEIFS(Keywords!$P$2:$P$97,Keywords!$B$2:$B$97,A13,Keywords!$C$2:$C$97,B13)
A14: 04 AI & Agentic Mobile Testing | B14: AI Mobile Testing | C14: =COUNTIFS(Keywords!$B$2:$B$97,A14,Keywords!$C$2:$C$97,B14) | D14: =SUMIFS(Keywords!$H$2:$H$97,Keywords!$B$2:$B$97,A14,Keywords!$C$2:$C$97,B14) | E14: =ROUND(AVERAGEIFS(Keywords!$Q$2:$Q$97,Keywords!$B$2:$B$97,A14,Keywords!$C$2:$C$97,B14),0) | F14: =COUNTIFS(Keywords!$B$2:$B$97,A14,Keywords!$C$2:$C$97,B14,Keywords!$R$2:$R$97,"Tier 1") | G14: =AVERAGEIFS(Keywords!$P$2:$P$97,Keywords!$B$2:$B$97,A14,Keywords!$C$2:$C$97,B14) | H14: 0.18 | I14: Reach QA leaders evaluating AI testing; crowded & expensive – manage CPA.
A15: 04 AI & Agentic Mobile Testing | B15: Agentic QA | C15: =COUNTIFS(Keywords!$B$2:$B$97,A15,Keywords!$C$2:$C$97,B15) | D15: =SUMIFS(Keywords!$H$2:$H$97,Keywords!$B$2:$B$97,A15,Keywords!$C$2:$C$97,B15) | E15: =ROUND(AVERAGEIFS(Keywords!$Q$2:$Q$97,Keywords!$B$2:$B$97,A15,Keywords!$C$2:$C$97,B15),0) | F15: =COUNTIFS(Keywords!$B$2:$B$97,A15,Keywords!$C$2:$C$97,B15,Keywords!$R$2:$R$97,"Tier 1") | G15: =AVERAGEIFS(Keywords!$P$2:$P$97,Keywords!$B$2:$B$97,A15,Keywords!$C$2:$C$97,B15)
A16: 04 AI & Agentic Mobile Testing | B16: Verify AI-Written Code | C16: =COUNTIFS(Keywords!$B$2:$B$97,A16,Keywords!$C$2:$C$97,B16) | D16: =SUMIFS(Keywords!$H$2:$H$97,Keywords!$B$2:$B$97,A16,Keywords!$C$2:$C$97,B16) | E16: =ROUND(AVERAGEIFS(Keywords!$Q$2:$Q$97,Keywords!$B$2:$B$97,A16,Keywords!$C$2:$C$97,B16),0) | F16: =COUNTIFS(Keywords!$B$2:$B$97,A16,Keywords!$C$2:$C$97,B16,Keywords!$R$2:$R$97,"Tier 1") | G16: =AVERAGEIFS(Keywords!$P$2:$P$97,Keywords!$B$2:$B$97,A16,Keywords!$C$2:$C$97,B16)
A17: 05 Competitor Conquest | B17: Limrun | C17: =COUNTIFS(Keywords!$B$2:$B$97,A17,Keywords!$C$2:$C$97,B17) | D17: =SUMIFS(Keywords!$H$2:$H$97,Keywords!$B$2:$B$97,A17,Keywords!$C$2:$C$97,B17) | E17: =ROUND(AVERAGEIFS(Keywords!$Q$2:$Q$97,Keywords!$B$2:$B$97,A17,Keywords!$C$2:$C$97,B17),0) | F17: =COUNTIFS(Keywords!$B$2:$B$97,A17,Keywords!$C$2:$C$97,B17,Keywords!$R$2:$R$97,"Tier 1") | G17: =AVERAGEIFS(Keywords!$P$2:$P$97,Keywords!$B$2:$B$97,A17,Keywords!$C$2:$C$97,B17) | H17: 0.15 | I17: Conquest Limrun, Expo EAS Simulator and incumbent device clouds; no trademarks in copy.
A18: 05 Competitor Conquest | B18: Expo EAS Simulator | C18: =COUNTIFS(Keywords!$B$2:$B$97,A18,Keywords!$C$2:$C$97,B18) | D18: =SUMIFS(Keywords!$H$2:$H$97,Keywords!$B$2:$B$97,A18,Keywords!$C$2:$C$97,B18) | E18: =ROUND(AVERAGEIFS(Keywords!$Q$2:$Q$97,Keywords!$B$2:$B$97,A18,Keywords!$C$2:$C$97,B18),0) | F18: =COUNTIFS(Keywords!$B$2:$B$97,A18,Keywords!$C$2:$C$97,B18,Keywords!$R$2:$R$97,"Tier 1") | G18: =AVERAGEIFS(Keywords!$P$2:$P$97,Keywords!$B$2:$B$97,A18,Keywords!$C$2:$C$97,B18)
A19: 05 Competitor Conquest | B19: Device Clouds | C19: =COUNTIFS(Keywords!$B$2:$B$97,A19,Keywords!$C$2:$C$97,B19) | D19: =SUMIFS(Keywords!$H$2:$H$97,Keywords!$B$2:$B$97,A19,Keywords!$C$2:$C$97,B19) | E19: =ROUND(AVERAGEIFS(Keywords!$Q$2:$Q$97,Keywords!$B$2:$B$97,A19,Keywords!$C$2:$C$97,B19),0) | F19: =COUNTIFS(Keywords!$B$2:$B$97,A19,Keywords!$C$2:$C$97,B19,Keywords!$R$2:$R$97,"Tier 1") | G19: =AVERAGEIFS(Keywords!$P$2:$P$97,Keywords!$B$2:$B$97,A19,Keywords!$C$2:$C$97,B19)
A20: 05 Competitor Conquest | B20: Remote Xcode | C20: =COUNTIFS(Keywords!$B$2:$B$97,A20,Keywords!$C$2:$C$97,B20) | D20: =SUMIFS(Keywords!$H$2:$H$97,Keywords!$B$2:$B$97,A20,Keywords!$C$2:$C$97,B20) | E20: =ROUND(AVERAGEIFS(Keywords!$Q$2:$Q$97,Keywords!$B$2:$B$97,A20,Keywords!$C$2:$C$97,B20),0) | F20: =COUNTIFS(Keywords!$B$2:$B$97,A20,Keywords!$C$2:$C$97,B20,Keywords!$R$2:$R$97,"Tier 1") | G20: =AVERAGEIFS(Keywords!$P$2:$P$97,Keywords!$B$2:$B$97,A20,Keywords!$C$2:$C$97,B20)
A21: 06 PR Preview & Build Review | B21: PR Preview | C21: =COUNTIFS(Keywords!$B$2:$B$97,A21,Keywords!$C$2:$C$97,B21) | D21: =SUMIFS(Keywords!$H$2:$H$97,Keywords!$B$2:$B$97,A21,Keywords!$C$2:$C$97,B21) | E21: =ROUND(AVERAGEIFS(Keywords!$Q$2:$Q$97,Keywords!$B$2:$B$97,A21,Keywords!$C$2:$C$97,B21),0) | F21: =COUNTIFS(Keywords!$B$2:$B$97,A21,Keywords!$C$2:$C$97,B21,Keywords!$R$2:$R$97,"Tier 1") | G21: =AVERAGEIFS(Keywords!$P$2:$P$97,Keywords!$B$2:$B$97,A21,Keywords!$C$2:$C$97,B21) | H21: 0.05 | I21: Secondary: PR preview/review use case for managers, design, PM.
A23: TOTAL | C23: =SUM(C2:C21) | D23: =SUM(D2:D21) | F23: =SUM(F2:F21) | H23: =SUM(H2:H21)
A25: Monthly search budget ($) | B25: 10000 | C25: ← placeholder; set your budget
A26: Campaign | B26: Monthly $ | C26: Daily $
A27: 01 Brand – Appetize AI | B27: =$B$25*H2 | C27: =B27/30.4
A28: 02 Agents × Mobile (MCP / CLI) | B28: =$B$25*H4 | C28: =B28/30.4
A29: 03 Cloud Simulators for Dev & CI | B29: =$B$25*H9 | C29: =B29/30.4
A30: 04 AI & Agentic Mobile Testing | B30: =$B$25*H14 | C30: =B30/30.4
A31: 05 Competitor Conquest | B31: =$B$25*H17 | C31: =B31/30.4
A32: 06 PR Preview & Build Review | B32: =$B$25*H21 | C32: =B32/30.4
A34: Plus: Demand Gen (Custom Segments) – recommend an additional 20–30% of search budget for awareness; see Audience Segments tab.

Sheet Scoring
A1: Input | B1: Value | C1: Notes
A2: Relevance weight (max pts) | B2: 60 | C2: Relevance 1–5 scaled to this many points
A3: Volume weight (max pts) | B3: 25 | C3: log10 scale; full points at the volume cap below
A4: Volume cap (searches/mo) | B4: 5000 | C4: Volume at which volume points max out
A5: Intent pts – Commercial / Navigational | B5: 15
A6: Intent pts – Solution-aware | B6: 10
A7: Intent pts – Informational | B7: 5
A8: Tier 1 threshold | B8: 85 | C8: Score ≥ this → Tier 1 (launch day 1, Phrase+Exact)
A9: Tier 2 threshold | B9: 72 | C9: Score ≥ this → Tier 2 (Phrase); below → Tier 3 (Exact, low bid)
A11: Formula: Score = RelW×(Relevance/5) + VolW×MIN(1, LOG10(Vol+1)/LOG10(Cap+1)) + IntentPts

Sheet Negatives
A1: Negative Keyword | B1: Match Type | C1: List | D1: Reason
A2: games | B2: Phrase | C2: Gaming / consumer emulators | D2: Consumer / gaming emulator intent – dominant in 'emulator online' queries
A3: gaming | B3: Phrase | C3: Gaming / consumer emulators | D3: Consumer / gaming emulator intent – dominant in 'emulator online' queries
A4: game | B4: Phrase | C4: Gaming / consumer emulators | D4: Consumer / gaming emulator intent – dominant in 'emulator online' queries
A5: bluestacks | B5: Phrase | C5: Gaming / consumer emulators | D5: Consumer / gaming emulator intent – dominant in 'emulator online' queries
A6: ldplayer | B6: Phrase | C6: Gaming / consumer emulators | D6: Consumer / gaming emulator intent – dominant in 'emulator online' queries
A7: noxplayer | B7: Phrase | C7: Gaming / consumer emulators | D7: Consumer / gaming emulator intent – dominant in 'emulator online' queries
A8: memu | B8: Phrase | C8: Gaming / consumer emulators | D8: Consumer / gaming emulator intent – dominant in 'emulator online' queries
A9: roblox | B9: Phrase | C9: Gaming / consumer emulators | D9: Consumer / gaming emulator intent – dominant in 'emulator online' queries
A10: pokemon | B10: Phrase | C10: Gaming / consumer emulators | D10: Consumer / gaming emulator intent – dominant in 'emulator online' queries
A11: free fire | B11: Phrase | C11: Gaming / consumer emulators | D11: Consumer / gaming emulator intent – dominant in 'emulator online' queries
A12: pubg | B12: Phrase | C12: Gaming / consumer emulators | D12: Consumer / gaming emulator intent – dominant in 'emulator online' queries
... A67: android phone deals | B67: Phrase | C67: Consumer phones | D67: Device shoppers

Sheet Ad Copy
A1: Campaign | B1: Asset Type | C1: Text | D1: Chars | E1: Limit | F1: OK?
A2: 02 Agents × Mobile (MCP / CLI) | B2: Headline | C2: The Mobile Layer for AI Agents | D2: =LEN(C2) | E2: 30 | F2: =IF(D2<=E2,"✓","TOO LONG")
A3: 02 Agents × Mobile (MCP / CLI) | B3: Headline | C3: Give Your Agent a Real Phone | D3: =LEN(C3) | E3: 30 | F3: =IF(D3<=E3,"✓","TOO LONG")
A4: 02 Agents × Mobile (MCP / CLI) | B4: Headline | C4: iOS & Android MCP in the Cloud | D4: =LEN(C4) | E4: 30 | F4: =IF(D4<=E4,"✓","TOO LONG")
A5: 02 Agents × Mobile (MCP / CLI) | B5: Headline | C5: Agents Run & Test Mobile Apps | D5: =LEN(C5) | E5: 30 | F5: =IF(D5<=E5,"✓","TOO LONG")
A6: 02 Agents × Mobile (MCP / CLI) | B6: Headline | C6: Mobile Sandbox for AI Agents | D6: =LEN(C6) | E6: 30 | F6: =IF(D6<=E6,"✓","TOO LONG")
A7: 02 Agents × Mobile (MCP / CLI) | B7: Headline | C7: One CLI. iOS + Android. | D7: =LEN(C7) | E7: 30 | F7: =IF(D7<=E7,"✓","TOO LONG")
A8: 02 Agents × Mobile (MCP / CLI) | B8: Headline | C8: Break the Phone Wall | D8: =LEN(C8) | E8: 30 | F8: =IF(D8<=E8,"✓","TOO LONG")
A9: 02 Agents × Mobile (MCP / CLI) | B9: Headline | C9: No Mac? No Problem. | D9: =LEN(C9) | E9: 30 | F9: =IF(D9<=E9,"✓","TOO LONG")
A10: 02 Agents × Mobile (MCP / CLI) | B10: Description | C10: Coding agents build, run & verify iOS and Android apps in cloud sandboxes via CLI or MCP. | D10: =LEN(C10) | E10: 90 | F10: =IF(D10<=E10,"✓","TOO LONG")
A11: 02 Agents × Mobile (MCP / CLI) | B11: Description | C11: Agents see the screen, tap, type and read logs & network traffic in isolated sessions. | D11: =LEN(C11) | E11: 90 | F11: =IF(D11<=E11,"✓","TOO LONG")
A12: 03 Cloud Simulators for Dev & CI | B12: Headline | C12: Cloud iOS Simulators via API | D12: =LEN(C12) | E12: 30 | F12: =IF(D12<=E12,"✓","TOO LONG")
A13: 03 Cloud Simulators for Dev & CI | B13: Headline | C13: iOS Simulator on Linux & CI | D13: =LEN(C13) | E13: 30 | F13: =IF(D13<=E13,"✓","TOO LONG")
... A28: 01 Brand – Appetize AI | B28: Description | C28: Appetize AI: cloud iOS & Android sandboxes for Claude Code, Cursor, Codex, Devin and CI. | D28: =LEN(C28) | E28: 90 | F28: =IF(D28<=E28,"✓","TOO LONG")
A30: Do not use competitor names in any asset.

Sheet Audience Segments
A1: Segment | B1: Type | C1: Seeds | D1: Use
A2: Agent-mobile searchers | B2: Custom segment – search terms | C2: ios simulator mcp; mobile mcp; xcode mcp; xcodebuildmcp; claude code ios; cursor ios development; appium mcp; android emulator mcp | D2: Demand Gen + YouTube awareness
A3: Competitor site visitors | B3: Custom segment – websites | C3: limrun.com; expo.dev/services/simulators; browserstack.com; saucelabs.com; lambdatest.com; genymotion.com; xcodebuildmcp.com; callstack.com | D3: Demand Gen; exclude existing customers
A4: OSS MCP / agent devs | B4: Custom segment – websites | C4: github.com/mobile-next/mobile-mcp; github.com/joshuayoes/ios-simulator-mcp; github.com/callstack/agent-device; glama.ai; mcpservers.org; claudemarketplaces.com | D4: Demand Gen (URL signals are directional)
A5: Coding agent users | B5: Custom segment – apps/sites | C5: claude.ai; cursor.com; openai.com/codex; devin.ai; github.com/features/copilot | D5: Layer with mobile interest to avoid waste
A6: Mobile dev interest | B6: Custom segment – search terms | C6: react native; swiftui; jetpack compose; expo eas; fastlane; bitrise; xcode 26 | D6: Layer / observation
A7: Site remarketing | B7: Your data | C7: Visitors to appetize.io/ai who didn't sign up; docs/CLI visitors | D7: Retarget with CLI quickstart / demo video
